Workbook

Sheet Summary Dashboard
M1: Date | N1: Item Name | O1: Category | P1: Quantity | Q1: Unit Price | R1: Total Cost
B2: Household Purchase Summary Dashboard | M2: =IFERROR(__xludf.DUMMYFUNCTION("QUERY({Jan!B3:G100; Feb!B3:G100; Mar!B3:G100; Apr!B3:G100; May!B3:G100; Jun!B3:G100; Jul!B3:G100; Aug!B3:G100; Sep!B3:G100; Oct!B3:G100; Nov!B3:G100; Dec!B3:G100}, ""select * where Col1 is not null"")"),"5/1/2026") | N2: =IFERROR(__xludf.DUMMYFUNCTION("""COMPUTED_VALUE"""),"Milk (1 Gal)") | O2: =IFERROR(__xludf.DUMMYFUNCTION("""COMPUTED_VALUE"""),"Groceries") | P2: =IFERROR(__xludf.DUMMYFUNCTION("""COMPUTED_VALUE"""),2.0) | Q2: =IFERROR(__xludf.DUMMYFUNCTION("""COMPUTED_VALUE"""),3.5) | R2: =IFERROR(__xludf.DUMMYFUNCTION("""COMPUTED_VALUE"""),7.0)
M3: =IFERROR(__xludf.DUMMYFUNCTION("""COMPUTED_VALUE"""),"12/1/2026") | N3: =IFERROR(__xludf.DUMMYFUNCTION("""COMPUTED_VALUE"""),"Electricity Bill") | O3: =IFERROR(__xludf.DUMMYFUNCTION("""COMPUTED_VALUE"""),"Utilities") | P3: =IFERROR(__xludf.DUMMYFUNCTION("""COMPUTED_VALUE"""),1.0) | Q3: =IFERROR(__xludf.DUMMYFUNCTION("""COMPUTED_VALUE"""),120.0) | R3: =IFERROR(__xludf.DUMMYFUNCTION("""COMPUTED_VALUE"""),120.0)
B4: Category Pivot Table | E4: Monthly Spending | M4: =IFERROR(__xludf.DUMMYFUNCTION("""COMPUTED_VALUE"""),"1/18/2026") | N4: =IFERROR(__xludf.DUMMYFUNCTION("""COMPUTED_VALUE"""),"Paper Towels") | O4: =IFERROR(__xludf.DUMMYFUNCTION("""COMPUTED_VALUE"""),"Household") | P4: =IFERROR(__xludf.DUMMYFUNCTION("""COMPUTED_VALUE"""),1.0) | Q4: =IFERROR(__xludf.DUMMYFUNCTION("""COMPUTED_VALUE"""),15.0) | R4: =IFERROR(__xludf.DUMMYFUNCTION("""COMPUTED_VALUE"""),15.0)
M5: =IFERROR(__xludf.DUMMYFUNCTION("""COMPUTED_VALUE"""),"1/25/2026") | N5: =IFERROR(__xludf.DUMMYFUNCTION("""COMPUTED_VALUE"""),"Apples") | O5: =IFERROR(__xludf.DUMMYFUNCTION("""COMPUTED_VALUE"""),"Groceries") | P5: =IFERROR(__xludf.DUMMYFUNCTION("""COMPUTED_VALUE"""),5.0) | Q5: =IFERROR(__xludf.DUMMYFUNCTION("""COMPUTED_VALUE"""),0.8) | R5: =IFERROR(__xludf.DUMMYFUNCTION("""COMPUTED_VALUE"""),4.0)
E6: Month | F6: Total Spending | M6: =IFERROR(__xludf.DUMMYFUNCTION("""COMPUTED_VALUE"""),"1/29/2026") | N6: =IFERROR(__xludf.DUMMYFUNCTION("""COMPUTED_VALUE"""),"Light Bulbs") | O6: =IFERROR(__xludf.DUMMYFUNCTION("""COMPUTED_VALUE"""),"Maintenance") | P6: =IFERROR(__xludf.DUMMYFUNCTION("""COMPUTED_VALUE"""),1.0) | Q6: =IFERROR(__xludf.DUMMYFUNCTION("""COMPUTED_VALUE"""),12.5) | R6: =IFERROR(__xludf.DUMMYFUNCTION("""COMPUTED_VALUE"""),12.5)
E7: Jan | F7: =SUM(Jan!G3:G100) | M7: =IFERROR(__xludf.DUMMYFUNCTION("""COMPUTED_VALUE"""),"2/2/2026") | N7: =IFERROR(__xludf.DUMMYFUNCTION("""COMPUTED_VALUE"""),"Water Bill") | O7: =IFERROR(__xludf.DUMMYFUNCTION("""COMPUTED_VALUE"""),"Utilities") | P7: =IFERROR(__xludf.DUMMYFUNCTION("""COMPUTED_VALUE"""),1.0) | Q7: =IFERROR(__xludf.DUMMYFUNCTION("""COMPUTED_VALUE"""),45.0) | R7: =IFERROR(__xludf.DUMMYFUNCTION("""COMPUTED_VALUE"""),45.0)
E8: Feb | F8: =SUM(Feb!G3:G100) | M8: =IFERROR(__xludf.DUMMYFUNCTION("""COMPUTED_VALUE"""),"10/2/2026") | N8: =IFERROR(__xludf.DUMMYFUNCTION("""COMPUTED_VALUE"""),"Bread") | O8: =IFERROR(__xludf.DUMMYFUNCTION("""COMPUTED_VALUE"""),"Groceries") | P8: =IFERROR(__xludf.DUMMYFUNCTION("""COMPUTED_VALUE"""),3.0) | Q8: =IFERROR(__xludf.DUMMYFUNCTION("""COMPUTED_VALUE"""),2.5) | R8: =IFERROR(__xludf.DUMMYFUNCTION("""COMPUTED_VALUE"""),7.5)
E9: Mar | F9: =SUM(Mar!G3:G100) | M9: =IFERROR(__xludf.DUMMYFUNCTION("""COMPUTED_VALUE"""),"2/15/2026") | N9: =IFERROR(__xludf.DUMMYFUNCTION("""COMPUTED_VALUE"""),"Internet") | O9: =IFERROR(__xludf.DUMMYFUNCTION("""COMPUTED_VALUE"""),"Utilities") | P9: =IFERROR(__xludf.DUMMYFUNCTION("""COMPUTED_VALUE"""),1.0) | Q9: =IFERROR(__xludf.DUMMYFUNCTION("""COMPUTED_VALUE"""),60.0) | R9: =IFERROR(__xludf.DUMMYFUNCTION("""COMPUTED_VALUE"""),60.0)
E10: Apr | F10: =SUM(Apr!G3:G100) | M10: =IFERROR(__xludf.DUMMYFUNCTION("""COMPUTED_VALUE"""),"2/20/2026") | N10: =IFERROR(__xludf.DUMMYFUNCTION("""COMPUTED_VALUE"""),"Chicken Breast") | O10: =IFERROR(__xludf.DUMMYFUNCTION("""COMPUTED_VALUE"""),"Groceries") | P10: =IFERROR(__xludf.DUMMYFUNCTION("""COMPUTED_VALUE"""),2.0) | Q10: =IFERROR(__xludf.DUMMYFUNCTION("""COMPUTED_VALUE"""),8.0) | R10: =IFERROR(__xludf.DUMMYFUNCTION("""COMPUTED_VALUE"""),16.0)
E11: May | F11: =SUM(May!G3:G100) | M11: =IFERROR(__xludf.DUMMYFUNCTION("""COMPUTED_VALUE"""),"5/3/2026") | N11: =IFERROR(__xludf.DUMMYFUNCTION("""COMPUTED_VALUE"""),"Gas Bill") | O11: =IFERROR(__xludf.DUMMYFUNCTION("""COMPUTED_VALUE"""),"Utilities") | P11: =IFERROR(__xludf.DUMMYFUNCTION("""COMPUTED_VALUE"""),1.0) | Q11: =IFERROR(__xludf.DUMMYFUNCTION("""COMPUTED_VALUE"""),80.0) | R11: =IFERROR(__xludf.DUMMYFUNCTION("""COMPUTED_VALUE"""),80.0)
E12: Jun | F12: =SUM(Jun!G3:G100) | M12: =IFERROR(__xludf.DUMMYFUNCTION("""COMPUTED_VALUE"""),"12/3/2026") | N12: =IFERROR(__xludf.DUMMYFUNCTION("""COMPUTED_VALUE"""),"Laundry Detergent") | O12: =IFERROR(__xludf.DUMMYFUNCTION("""COMPUTED_VALUE"""),"Household") | P12: =IFERROR(__xludf.DUMMYFUNCTION("""COMPUTED_VALUE"""),1.0) | Q12: =IFERROR(__xludf.DUMMYFUNCTION("""COMPUTED_VALUE"""),18.0) | R12: =IFERROR(__xludf.DUMMYFUNCTION("""COMPUTED_VALUE"""),18.0)
E13: Jul | F13: =SUM(Jul!G3:G100) | M13: =IFERROR(__xludf.DUMMYFUNCTION("""COMPUTED_VALUE"""),"3/18/2026") | N13: =IFERROR(__xludf.DUMMYFUNCTION("""COMPUTED_VALUE"""),"Eggs (1 Dozen)") | O13: =IFERROR(__xludf.DUMMYFUNCTION("""COMPUTED_VALUE"""),"Groceries") | P13: =IFERROR(__xludf.DUMMYFUNCTION("""COMPUTED_VALUE"""),2.0) | Q13: =IFERROR(__xludf.DUMMYFUNCTION("""COMPUTED_VALUE"""),4.0) | R13: =IFERROR(__xludf.DUMMYFUNCTION("""COMPUTED_VALUE"""),8.0)
E14: Aug | F14: =SUM(Aug!G3:G100) | M14: =IFERROR(__xludf.DUMMYFUNCTION("""COMPUTED_VALUE"""),"3/22/2026") | N14: =IFERROR(__xludf.DUMMYFUNCTION("""COMPUTED_VALUE"""),"Trash Bags") | O14: =IFERROR(__xludf.DUMMYFUNCTION("""COMPUTED_VALUE"""),"Household") | P14: =IFERROR(__xludf.DUMMYFUNCTION("""COMPUTED_VALUE"""),1.0) | Q14: =IFERROR(__xludf.DUMMYFUNCTION("""COMPUTED_VALUE"""),10.0) | R14: =IFERROR(__xludf.DUMMYFUNCTION("""COMPUTED_VALUE"""),10.0)
E15: Sep | F15: =SUM(Sep!G3:G100) | M15: =IFERROR(__xludf.DUMMYFUNCTION("""COMPUTED_VALUE"""),"2/4/2026") | N15: =IFERROR(__xludf.DUMMYFUNCTION("""COMPUTED_VALUE"""),"Milk (1 Gal)") | O15: =IFERROR(__xludf.DUMMYFUNCTION("""COMPUTED_VALUE"""),"Groceries") | P15: =IFERROR(__xludf.DUMMYFUNCTION("""COMPUTED_VALUE"""),2.0) | Q15: =IFERROR(__xludf.DUMMYFUNCTION("""COMPUTED_VALUE"""),3.5) | R15: =IFERROR(__xludf.DUMMYFUNCTION("""COMPUTED_VALUE"""),7.0)
E16: Oct | F16: =SUM(Oct!G3:G100) | M16: =IFERROR(__xludf.DUMMYFUNCTION("""COMPUTED_VALUE"""),"10/4/2026") | N16: =IFERROR(__xludf.DUMMYFUNCTION("""COMPUTED_VALUE"""),"Electricity Bill") | O16: =IFERROR(__xludf.DUMMYFUNCTION("""COMPUTED_VALUE"""),"Utilities") | P16: =IFERROR(__xludf.DUMMYFUNCTION("""COMPUTED_VALUE"""),1.0) | Q16: =IFERROR(__xludf.DUMMYFUNCTION("""COMPUTED_VALUE"""),115.0) | R16: =IFERROR(__xludf.DUMMYFUNCTION("""COMPUTED_VALUE"""),115.0)
E17: Nov | F17: =SUM(Nov!G3:G100) | M17: =IFERROR(__xludf.DUMMYFUNCTION("""COMPUTED_VALUE"""),"4/15/2026") | N17: =IFERROR(__xludf.DUMMYFUNCTION("""COMPUTED_VALUE"""),"Toothpaste") | O17: =IFERROR(__xludf.DUMMYFUNCTION("""COMPUTED_VALUE"""),"Personal Care") | P17: =IFERROR(__xludf.DUMMYFUNCTION("""COMPUTED_VALUE"""),2.0) | Q17: =IFERROR(__xludf.DUMMYFUNCTION("""COMPUTED_VALUE"""),4.5) | R17: =IFERROR(__xludf.DUMMYFUNCTION("""COMPUTED_VALUE"""),9.0)
E18: Dec | F18: =SUM(Dec!G3:G100) | M18: =IFERROR(__xludf.DUMMYFUNCTION("""COMPUTED_VALUE"""),"4/25/2026") | N18: =IFERROR(__xludf.DUMMYFUNCTION("""COMPUTED_VALUE"""),"Bananas") | O18: =IFERROR(__xludf.DUMMYFUNCTION("""COMPUTED_VALUE"""),"Groceries") | P18: =IFERROR(__xludf.DUMMYFUNCTION("""COMPUTED_VALUE"""),6.0) | Q18: =IFERROR(__xludf.DUMMYFUNCTION("""COMPUTED_VALUE"""),0.5) | R18: =IFERROR(__xludf.DUMMYFUNCTION("""COMPUTED_VALUE"""),3.0)
M19: =IFERROR(__xludf.DUMMYFUNCTION("""COMPUTED_VALUE"""),"1/5/2026") | N19: =IFERROR(__xludf.DUMMYFUNCTION("""COMPUTED_VALUE"""),"Water Bill") | O19: =IFERROR(__xludf.DUMMYFUNCTION("""COMPUTED_VALUE"""),"Utilities") | P19: =IFERROR(__xludf.DUMMYFUNCTION("""COMPUTED_VALUE"""),1.0) | Q19: =IFERROR(__xludf.DUMMYFUNCTION("""COMPUTED_VALUE"""),48.0) | R19: =IFERROR(__xludf.DUMMYFUNCTION("""COMPUTED_VALUE"""),48.0)
M20: =IFERROR(__xludf.DUMMYFUNCTION("""COMPUTED_VALUE"""),"8/5/2026") | N20: =IFERROR(__xludf.DUMMYFUNCTION("""COMPUTED_VALUE"""),"Coffee Beans") | O20: =IFERROR(__xludf.DUMMYFUNCTION("""COMPUTED_VALUE"""),"Groceries") | P20: =IFERROR(__xludf.DUMMYFUNCTION("""COMPUTED_VALUE"""),1.0) | Q20: =IFERROR(__xludf.DUMMYFUNCTION("""COMPUTED_VALUE"""),14.0) | R20: =IFERROR(__xludf.DUMMYFUNCTION("""COMPUTED_VALUE"""),14.0)
M21: =IFERROR(__xludf.DUMMYFUNCTION("""COMPUTED_VALUE"""),"5/15/2026") | N21: =IFERROR(__xludf.DUMMYFUNCTION("""COMPUTED_VALUE"""),"Internet") | O21: =IFERROR(__xludf.DUMMYFUNCTION("""COMPUTED_VALUE"""),"Utilities") | P21: =IFERROR(__xludf.DUMMYFUNCTION("""COMPUTED_VALUE"""),1.0) | Q21: =IFERROR(__xludf.DUMMYFUNCTION("""COMPUTED_VALUE"""),60.0) | R21: =IFERROR(__xludf.DUMMYFUNCTION("""COMPUTED_VALUE"""),60.0)
M22: =IFERROR(__xludf.DUMMYFUNCTION("""COMPUTED_VALUE"""),"5/20/2026") | N22: =IFERROR(__xludf.DUMMYFUNCTION("""COMPUTED_VALUE"""),"Dish Soap") | O22: =IFERROR(__xludf.DUMMYFUNCTION("""COMPUTED_VALUE"""),"Household") | P22: =IFERROR(__xludf.DUMMYFUNCTION("""COMPUTED_VALUE"""),1.0) | Q22: =IFERROR(__xludf.DUMMYFUNCTION("""COMPUTED_VALUE"""),4.0) | R22: =IFERROR(__xludf.DUMMYFUNCTION("""COMPUTED_VALUE"""),4.0)
M23: =IFERROR(__xludf.DUMMYFUNCTION("""COMPUTED_VALUE"""),"5/6/2026") | N23: =IFERROR(__xludf.DUMMYFUNCTION("""COMPUTED_VALUE"""),"Gas Bill") | O23: =IFERROR(__xludf.DUMMYFUNCTION("""COMPUTED_VALUE"""),"Utilities") | P23: =IFERROR(__xludf.DUMMYFUNCTION("""COMPUTED_VALUE"""),1.0) | Q23: =IFERROR(__xludf.DUMMYFUNCTION("""COMPUTED_VALUE"""),35.0) | R23: =IFERROR(__xludf.DUMMYFUNCTION("""COMPUTED_VALUE"""),35.0)
M24: =IFERROR(__xludf.DUMMYFUNCTION("""COMPUTED_VALUE"""),"12/6/2026") | N24: =IFERROR(__xludf.DUMMYFUNCTION("""COMPUTED_VALUE"""),"Beef Mince") | O24: =IFERROR(__xludf.DUMMYFUNCTION("""COMPUTED_VALUE"""),"Groceries") | P24: =IFERROR(__xludf.DUMMYFUNCTION("""COMPUTED_VALUE"""),2.0) | Q24: =IFERROR(__xludf.DUMMYFUNCTION("""COMPUTED_VALUE"""),7.5) | R24: =IFERROR(__xludf.DUMMYFUNCTION("""COMPUTED_VALUE"""),15.0)
M25: =IFERROR(__xludf.DUMMYFUNCTION("""COMPUTED_VALUE"""),"6/18/2026") | N25: =IFERROR(__xludf.DUMMYFUNCTION("""COMPUTED_VALUE"""),"Shampoo") | O25: =IFERROR(__xludf.DUMMYFUNCTION("""COMPUTED_VALUE"""),"Personal Care") | P25: =IFERROR(__xludf.DUMMYFUNCTION("""COMPUTED_VALUE"""),1.0) | Q25: =IFERROR(__xludf.DUMMYFUNCTION("""COMPUTED_VALUE"""),6.0) | R25: =IFERROR(__xludf.DUMMYFUNCTION("""COMPUTED_VALUE"""),6.0)
M26: =IFERROR(__xludf.DUMMYFUNCTION("""COMPUTED_VALUE"""),"6/25/2026") | N26: =IFERROR(__xludf.DUMMYFUNCTION("""COMPUTED_VALUE"""),"Batteries (AA)") | O26: =IFERROR(__xludf.DUMMYFUNCTION("""COMPUTED_VALUE"""),"Electronics") | P26: =IFERROR(__xludf.DUMMYFUNCTION("""COMPUTED_VALUE"""),1.0) | Q26: =IFERROR(__xludf.DUMMYFUNCTION("""COMPUTED_VALUE"""),15.0) | R26: =IFERROR(__xludf.DUMMYFUNCTION("""COMPUTED_VALUE"""),15.0)
M27: =IFERROR(__xludf.DUMMYFUNCTION("""COMPUTED_VALUE"""),"3/7/2026") | N27: =IFERROR(__xludf.DUMMYFUNCTION("""COMPUTED_VALUE"""),"Milk (1 Gal)") | O27: =IFERROR(__xludf.DUMMYFUNCTION("""COMPUTED_VALUE"""),"Groceries") | P27: =IFERROR(__xludf.DUMMYFUNCTION("""COMPUTED_VALUE"""),2.0) | Q27: =IFERROR(__xludf.DUMMYFUNCTION("""COMPUTED_VALUE"""),3.5) | R27: =IFERROR(__xludf.DUMMYFUNCTION("""COMPUTED_VALUE"""),7.0)
M28: =IFERROR(__xludf.DUMMYFUNCTION("""COMPUTED_VALUE"""),"10/7/2026") | N28: =IFERROR(__xludf.DUMMYFUNCTION("""COMPUTED_VALUE"""),"Electricity Bill") | O28: =IFERROR(__xludf.DUMMYFUNCTION("""COMPUTED_VALUE"""),"Utilities") | P28: =IFERROR(__xludf.DUMMYFUNCTION("""COMPUTED_VALUE"""),1.0) | Q28: =IFERROR(__xludf.DUMMYFUNCTION("""COMPUTED_VALUE"""),150.0) | R28: =IFERROR(__xludf.DUMMYFUNCTION("""COMPUTED_VALUE"""),150.0)
M29: =IFERROR(__xludf.DUMMYFUNCTION("""COMPUTED_VALUE"""),"7/15/2026") | N29: =IFERROR(__xludf.DUMMYFUNCTION("""COMPUTED_VALUE"""),"Sunscreen") | O29: =IFERROR(__xludf.DUMMYFUNCTION("""COMPUTED_VALUE"""),"Personal Care") | P29: =IFERROR(__xludf.DUMMYFUNCTION("""COMPUTED_VALUE"""),1.0) | Q29: =IFERROR(__xludf.DUMMYFUNCTION("""COMPUTED_VALUE"""),12.0) | R29: =IFERROR(__xludf.DUMMYFUNCTION("""COMPUTED_VALUE"""),12.0)
M30: =IFERROR(__xludf.DUMMYFUNCTION("""COMPUTED_VALUE"""),"7/22/2026") | N30: =IFERROR(__xludf.DUMMYFUNCTION("""COMPUTED_VALUE"""),"Pasta") | O30: =IFERROR(__xludf.DUMMYFUNCTION("""COMPUTED_VALUE"""),"Groceries") | P30: =IFERROR(__xludf.DUMMYFUNCTION("""COMPUTED_VALUE"""),4.0) | Q30: =IFERROR(__xludf.DUMMYFUNCTION("""COMPUTED_VALUE"""),1.5) | R30: =IFERROR(__xludf.DUMMYFUNCTION("""COMPUTED_VALUE"""),6.0)
M31: =IFERROR(__xludf.DUMMYFUNCTION("""COMPUTED_VALUE"""),"2/8/2026") | N31: =IFERROR(__xludf.DUMMYFUNCTION("""COMPUTED_VALUE"""),"Water Bill") | O31: =IFERROR(__xludf.DUMMYFUNCTION("""COMPUTED_VALUE"""),"Utilities") | P31: =IFERROR(__xludf.DUMMYFUNCTION("""COMPUTED_VALUE"""),1.0) | Q31: =IFERROR(__xludf.DUMMYFUNCTION("""COMPUTED_VALUE"""),55.0) | R31: =IFERROR(__xludf.DUMMYFUNCTION("""COMPUTED_VALUE"""),55.0)
M32: =IFERROR(__xludf.DUMMYFUNCTION("""COMPUTED_VALUE"""),"9/8/2026") | N32: =IFERROR(__xludf.DUMMYFUNCTION("""COMPUTED_VALUE"""),"Cereal") | O32: =IFERROR(__xludf.DUMMYFUNCTION("""COMPUTED_VALUE"""),"Groceries") | P32: =IFERROR(__xludf.DUMMYFUNCTION("""COMPUTED_VALUE"""),2.0) | Q32: =IFERROR(__xludf.DUMMYFUNCTION("""COMPUTED_VALUE"""),4.5) | R32: =IFERROR(__xludf.DUMMYFUNCTION("""COMPUTED_VALUE"""),9.0)
M33: =IFERROR(__xludf.DUMMYFUNCTION("""COMPUTED_VALUE"""),"8/15/2026") | N33: =IFERROR(__xludf.DUMMYFUNCTION("""COMPUTED_VALUE"""),"Internet") | O33: =IFERROR(__xludf.DUMMYFUNCTION("""COMPUTED_VALUE"""),"Utilities") | P33: =IFERROR(__xludf.DUMMYFUNCTION("""COMPUTED_VALUE"""),1.0) | Q33: =IFERROR(__xludf.DUMMYFUNCTION("""COMPUTED_VALUE"""),60.0) | R33: =IFERROR(__xludf.DUMMYFUNCTION("""COMPUTED_VALUE"""),60.0)
M34: =IFERROR(__xludf.DUMMYFUNCTION("""COMPUTED_VALUE"""),"8/20/2026") | N34: =IFERROR(__xludf.DUMMYFUNCTION("""COMPUTED_VALUE"""),"Toilet Paper") | O34: =IFERROR(__xludf.DUMMYFUNCTION("""COMPUTED_VALUE"""),"Household") | P34: =IFERROR(__xludf.DUMMYFUNCTION("""COMPUTED_VALUE"""),1.0) | Q34: =IFERROR(__xludf.DUMMYFUNCTION("""COMPUTED_VALUE"""),20.0) | R34: =IFERROR(__xludf.DUMMYFUNCTION("""COMPUTED_VALUE"""),20.0)
M35: =IFERROR(__xludf.DUMMYFUNCTION("""COMPUTED_VALUE"""),"8/28/2026") | N35: =IFERROR(__xludf.DUMMYFUNCTION("""COMPUTED_VALUE"""),"HDMI Cable") | O35: =IFERROR(__xludf.DUMMYFUNCTION("""COMPUTED_VALUE"""),"Electronics") | P35: =IFERROR(__xludf.DUMMYFUNCTION("""COMPUTED_VALUE"""),1.0) | Q35: =IFERROR(__xludf.DUMMYFUNCTION("""COMPUTED_VALUE"""),10.0) | R35: =IFERROR(__xludf.DUMMYFUNCTION("""COMPUTED_VALUE"""),10.0)
M36: =IFERROR(__xludf.DUMMYFUNCTION("""COMPUTED_VALUE"""),"5/9/2026") | N36: =IFERROR(__xludf.DUMMYFUNCTION("""COMPUTED_VALUE"""),"Gas Bill") | O36: =IFERROR(__xludf.DUMMYFUNCTION("""COMPUTED_VALUE"""),"Utilities") | P36: =IFERROR(__xludf.DUMMYFUNCTION("""COMPUTED_VALUE"""),1.0) | Q36: =IFERROR(__xludf.DUMMYFUNCTION("""COMPUTED_VALUE"""),40.0) | R36: =IFERROR(__xludf.DUMMYFUNCTION("""COMPUTED_VALUE"""),40.0)
M37: =IFERROR(__xludf.DUMMYFUNCTION("""COMPUTED_VALUE"""),"12/9/2026") | N37: =IFERROR(__xludf.DUMMYFUNCTION("""COMPUTED_VALUE"""),"Chicken Breast") | O37: =IFERROR(__xludf.DUMMYFUNCTION("""COMPUTED_VALUE"""),"Groceries") | P37: =IFERROR(__xludf.DUMMYFUNCTION("""COMPUTED_VALUE"""),2.0) | Q37: =IFERROR(__xludf.DUMMYFUNCTION("""COMPUTED_VALUE"""),8.0) | R37: =IFERROR(__xludf.DUMMYFUNCTION("""COMPUTED_VALUE"""),16.0)
M38: =IFERROR(__xludf.DUMMYFUNCTION("""COMPUTED_VALUE"""),"9/18/2026") | N38: =IFERROR(__xludf.DUMMYFUNCTION("""COMPUTED_VALUE"""),"Hand Soap") | O38: =IFERROR(__xludf.DUMMYFUNCTION("""COMPUTED_VALUE"""),"Personal Care") | P38: =IFERROR(__xludf.DUMMYFUNCTION("""COMPUTED_VALUE"""),2.0) | Q38: =IFERROR(__xludf.DUMMYFUNCTION("""COMPUTED_VALUE"""),3.0) | R38: =IFERROR(__xludf.DUMMYFUNCTION("""COMPUTED_VALUE"""),6.0)
M39: =IFERROR(__xludf.DUMMYFUNCTION("""COMPUTED_VALUE"""),"9/25/2026") | N39: =IFERROR(__xludf.DUMMYFUNCTION("""COMPUTED_VALUE"""),"Air Filters") | O39: =IFERROR(__xludf.DUMMYFUNCTION("""COMPUTED_VALUE"""),"Maintenance") | P39: =IFERROR(__xludf.DUMMYFUNCTION("""COMPUTED_VALUE"""),2.0) | Q39: =IFERROR(__xludf.DUMMYFUNCTION("""COMPUTED_VALUE"""),15.0) | R39: =IFERROR(__xludf.DUMMYFUNCTION("""COMPUTED_VALUE"""),30.0)
M40: =IFERROR(__xludf.DUMMYFUNCTION("""COMPUTED_VALUE"""),"2/10/2026") | N40: =IFERROR(__xludf.DUMMYFUNCTION("""COMPUTED_VALUE"""),"Milk (1 Gal)") | O40: =IFERROR(__xludf.DUMMYFUNCTION("""COMPUTED_VALUE"""),"Groceries") | P40: =IFERROR(__xludf.DUMMYFUNCTION("""COMPUTED_VALUE"""),2.0) | Q40: =IFERROR(__xludf.DUMMYFUNCTION("""COMPUTED_VALUE"""),3.5) | R40: =IFERROR(__xludf.DUMMYFUNCTION("""COMPUTED_VALUE"""),7.0)
...

Sheet Jan
A1: Jan
B2: Date | C2: Item Name | D2: Category | E2: Quantity | F2: Unit Price | G2: Total Cost
B3: 46143 | C3: Milk (1 Gal) | D3: Groceries | E3: 2 | F3: 3.5 | G3: =IF(ISBLANK(C3), "", E3*F3)
B4: 46357 | C4: Electricity Bill | D4: Utilities | E4: 1 | F4: 120 | G4: =IF(ISBLANK(C4), "", E4*F4)
B5: 1/18/2026 | C5: Paper Towels | D5: Household | E5: 1 | F5: 15 | G5: =IF(ISBLANK(C5), "", E5*F5)
B6: 1/25/2026 | C6: Apples | D6: Groceries | E6: 5 | F6: 0.8 | G6: =IF(ISBLANK(C6), "", E6*F6)
B7: 1/29/2026 | C7: Light Bulbs | D7: Maintenance | E7: 1 | F7: 12.5 | G7: =IF(ISBLANK(C7), "", E7*F7)

Sheet Feb
A1: Feb
B2: Date | C2: Item Name | D2: Category | E2: Quantity | F2: Unit Price | G2: Total Cost
B3: 46055 | C3: Water Bill | D3: Utilities | E3: 1 | F3: 45 | G3: =IF(ISBLANK(C3), "", E3*F3)
B4: 46297 | C4: Bread | D4: Groceries | E4: 3 | F4: 2.5 | G4: =IF(ISBLANK(C4), "", E4*F4)
B5: 2/15/2026 | C5: Internet | D5: Utilities | E5: 1 | F5: 60 | G5: =IF(ISBLANK(C5), "", E5*F5)
B6: 2/20/2026 | C6: Chicken Breast | D6: Groceries | E6: 2 | F6: 8 | G6: =IF(ISBLANK(C6), "", E6*F6)

Sheet Mar
A1: Mar
B2: Date | C2: Item Name | D2: Category | E2: Quantity | F2: Unit Price | G2: Total Cost
B3: 46145 | C3: Gas Bill | D3: Utilities | E3: 1 | F3: 80 | G3: =IF(ISBLANK(C3), "", E3*F3)
B4: 46359 | C4: Laundry Detergent | D4: Household | E4: 1 | F4: 18 | G4: =IF(ISBLANK(C4), "", E4*F4)
B5: 3/18/2026 | C5: Eggs (1 Dozen) | D5: Groceries | E5: 2 | F5: 4 | G5: =IF(ISBLANK(C5), "", E5*F5)
B6: 3/22/2026 | C6: Trash Bags | D6: Household | E6: 1 | F6: 10 | G6: =IF(ISBLANK(C6), "", E6*F6)

Sheet Apr
A1: Apr
B2: Date | C2: Item Name | D2: Category | E2: Quantity | F2: Unit Price | G2: Total Cost
B3: 46057 | C3: Milk (1 Gal) | D3: Groceries | E3: 2 | F3: 3.5 | G3: =IF(ISBLANK(C3), "", E3*F3)
B4: 46299 | C4: Electricity Bill | D4: Utilities | E4: 1 | F4: 115 | G4: =IF(ISBLANK(C4), "", E4*F4)
B5: 4/15/2026 | C5: Toothpaste | D5: Personal Care | E5: 2 | F5: 4.5 | G5: =IF(ISBLANK(C5), "", E5*F5)
B6: 4/25/2026 | C6: Bananas | D6: Groceries | E6: 6 | F6: 0.5 | G6: =IF(ISBLANK(C6), "", E6*F6)

Sheet May
A1: May
B2: Date | C2: Item Name | D2: Category | E2: Quantity | F2: Unit Price | G2: Total Cost
B3: 46027 | C3: Water Bill | D3: Utilities | E3: 1 | F3: 48 | G3: =IF(ISBLANK(C3), "", E3*F3)
B4: 46239 | C4: Coffee Beans | D4: Groceries | E4: 1 | F4: 14 | G4: =IF(ISBLANK(C4), "", E4*F4)
B5: 5/15/2026 | C5: Internet | D5: Utilities | E5: 1 | F5: 60 | G5: =IF(ISBLANK(C5), "", E5*F5)
B6: 5/20/2026 | C6: Dish Soap | D6: Household | E6: 1 | F6: 4 | G6: =IF(ISBLANK(C6), "", E6*F6)

Sheet Jun
A1: Jun
B2: Date | C2: Item Name | D2: Category | E2: Quantity | F2: Unit Price | G2: Total Cost
B3: 46148 | C3: Gas Bill | D3: Utilities | E3: 1 | F3: 35 | G3: =IF(ISBLANK(C3), "", E3*F3)
B4: 46362 | C4: Beef Mince | D4: Groceries | E4: 2 | F4: 7.5 | G4: =IF(ISBLANK(C4), "", E4*F4)
B5: 6/18/2026 | C5: Shampoo | D5: Personal Care | E5: 1 | F5: 6 | G5: =IF(ISBLANK(C5), "", E5*F5)
B6: 6/25/2026 | C6: Batteries (AA) | D6: Electronics | E6: 1 | F6: 15 | G6: =IF(ISBLANK(C6), "", E6*F6)

Sheet Jul
A1: Jul
B2: Date | C2: Item Name | D2: Category | E2: Quantity | F2: Unit Price | G2: Total Cost
B3: 46088 | C3: Milk (1 Gal) | D3: Groceries | E3: 2 | F3: 3.5 | G3: =IF(ISBLANK(C3), "", E3*F3)
B4: 46302 | C4: Electricity Bill | D4: Utilities | E4: 1 | F4: 150 | G4: =IF(ISBLANK(C4), "", E4*F4)
B5: 7/15/2026 | C5: Sunscreen | D5: Personal Care | E5: 1 | F5: 12 | G5: =IF(ISBLANK(C5), "", E5*F5)
B6: 7/22/2026 | C6: Pasta | D6: Groceries | E6: 4 | F6: 1.5 | G6: =IF(ISBLANK(C6), "", E6*F6)

Sheet Aug
A1: Aug
B2: Date | C2: Item Name | D2: Category | E2: Quantity | F2: Unit Price | G2: Total Cost
B3: 46061 | C3: Water Bill | D3: Utilities | E3: 1 | F3: 55 | G3: =IF(ISBLANK(C3), "", E3*F3)
B4: 46273 | C4: Cereal | D4: Groceries | E4: 2 | F4: 4.5 | G4: =IF(ISBLANK(C4), "", E4*F4)
B5: 8/15/2026 | C5: Internet | D5: Utilities | E5: 1 | F5: 60 | G5: =IF(ISBLANK(C5), "", E5*F5)
B6: 8/20/2026 | C6: Toilet Paper | D6: Household | E6: 1 | F6: 20 | G6: =IF(ISBLANK(C6), "", E6*F6)
B7: 8/28/2026 | C7: HDMI Cable | D7: Electronics | E7: 1 | F7: 10 | G7: =IF(ISBLANK(C7), "", E7*F7)

Sheet Sep
A1: Sep
B2: Date | C2: Item Name | D2: Category | E2: Quantity | F2: Unit Price | G2: Total Cost
B3: 46151 | C3: Gas Bill | D3: Utilities | E3: 1 | F3: 40 | G3: =IF(ISBLANK(C3), "", E3*F3)
B4: 46365 | C4: Chicken Breast | D4: Groceries | E4: 2 | F4: 8 | G4: =IF(ISBLANK(C4), "", E4*F4)
B5: 9/18/2026 | C5: Hand Soap | D5: Personal Care | E5: 2 | F5: 3 | G5: =IF(ISBLANK(C5), "", E5*F5)
B6: 9/25/2026 | C6: Air Filters | D6: Maintenance | E6: 2 | F6: 15 | G6: =IF(ISBLANK(C6), "", E6*F6)

Sheet Oct
A1: Oct
B2: Date | C2: Item Name | D2: Category | E2: Quantity | F2: Unit Price | G2: Total Cost
B3: 46063 | C3: Milk (1 Gal) | D3: Groceries | E3: 2 | F3: 3.5 | G3: =IF(ISBLANK(C3), "", E3*F3)
B4: 46305 | C4: Electricity Bill | D4: Utilities | E4: 1 | F4: 110 | G4: =IF(ISBLANK(C4), "", E4*F4)
B5: 10/15/2026 | C5: Halloween Candy | D5: Groceries | E5: 3 | F5: 6 | G5: =IF(ISBLANK(C5), "", E5*F5)
B6: 10/22/2026 | C6: Sponges | D6: Household | E6: 1 | F6: 5 | G6: =IF(ISBLANK(C6), "", E6*F6)

Sheet Nov
A1: Nov
B2: Date | C2: Item Name | D2: Category | E2: Quantity | F2: Unit Price | G2: Total Cost
B3: 46033 | C3: Water Bill | D3: Utilities | E3: 1 | F3: 45 | G3: =IF(ISBLANK(C3), "", E3*F3)
B4: 46245 | C4: Turkey | D4: Groceries | E4: 1 | F4: 25 | G4: =IF(ISBLANK(C4), "", E4*F4)
B5: 11/15/2026 | C5: Internet | D5: Utilities | E5: 1 | F5: 60 | G5: =IF(ISBLANK(C5), "", E5*F5)
B6: 11/20/2026 | C6: Tissues | D6: Household | E6: 2 | F6: 4 | G6: =IF(ISBLANK(C6), "", E6*F6)

Sheet Dec
A1: Dec
B2: Date | C2: Item Name | D2: Category | E2: Quantity | F2: Unit Price | G2: Total Cost
B3: 46154 | C3: Gas Bill | D3: Utilities | E3: 1 | F3: 95 | G3: =IF(ISBLANK(C3), "", E3*F3)
B4: 46368 | C4: Wrapping Paper | D4: Miscellaneous | E4: 3 | F4: 5 | G4: =IF(ISBLANK(C4), "", E4*F4)
B5: 12/18/2026 | C5: Potatoes | D5: Groceries | E5: 1 | F5: 4 | G5: =IF(ISBLANK(C5), "", E5*F5)
B6: 12/22/2026 | C6: Electricity Bill | D6: Utilities | E6: 1 | F6: 130 | G6: =IF(ISBLANK(C6), "", E6*F6)
B7: 12/28/2026 | C7: Batteries (AAA) | D7: Electronics | E7: 1 | F7: 12 | G7: =IF(ISBLANK(C7), "", E7*F7)
